`redis.exceptions.ConnectionError: Connection closed by server.                                                                                                                        [2022-09-28 20:39:41,738: WARNING/MainProcess] /usr/local/lib/python3.10/site-packages/celery/worker/consumer/consumer.py:361: CPendingDeprecationWarning:                            In Celery 5.1 we introduced an optional breaking change which                                                                                                                         on connection loss cancels all currently executed tasks with late acknowledgement enabled.                                                                                            These tasks cannot be acknowledged as the connection is gone, and the tasks are automatically redelivered back to the queue.                                                          You can enable this behavior using the worker_cancel_long_running_tasks_on_connection_loss setting.                                                                                   In Celery 5.1 it is set to False by default. The setting will be set to True by default in Celery 6.0.                                                                                                                                                                                                                                                                        warnings.warn(CANCEL_TASKS_BY_DEFAULT, CPendingDeprecationWarning)                                                                                                                                                                                                                                                                                                        [2022-09-28 20:39:41,793: ERROR/MainProcess] consumer: Cannot connect to redis://redis:6379/0: Error 111 connecting to redis:6379. Connection refused..                               Trying again in 2.00 seconds... (1/100)                                                                                                                                                                                                                                                                                                                                     [2022-09-28 20:39:43,801: ERROR/MainProcess] consumer: Cannot connect to redis://redis:6379/0: Error -3 connecting to redis:6379. Temporary failure in name resolution..              Trying again in 4.00 seconds... (2/100)                                                                                                                                         `